Workbook
Name MP: '[1]MATERIA PRIMA'!$B$3:$B$135

Sheet Descuentos para BOT 
A1: Legajo | B1: Nombre | C1: FECHA | D1: PROVEEDOR | E1: COMPROBANTE | F1: ARTICULO | G1: LEYENDA | H1: IMPORTE_GABI
A2: =VLOOKUP(B2,' Empleados c nro legajo'!B:C,2,FALSE) -> 60 | B2: Acuna, Santiago Martin | C2: 46081 | D2: YPF SOCIEDAD ANONIMA | E2: FGAS 1420 67511 | F2: Combustibles | G2: YPF - COMBUSTIBLE (AB411KE) | H2: $77.261,25
A3: =VLOOKUP(B3,' Empleados c nro legajo'!B:C,2,FALSE) -> 60 | B3: Acuna, Santiago Martin | C3: 46081 | D3: YPF SOCIEDAD ANONIMA | E3: FGAS 1420 67511 | F3: Combustibles | G3: YPF - COMBUSTIBLE (HQN489) | H3: $39.300,42
A4: =VLOOKUP(B4,' Empleados c nro legajo'!B:C,2,FALSE) -> 60 | B4: Acuna, Santiago Martin | C4: 46081 | D4: YPF SOCIEDAD ANONIMA | E4: FGAS 1420 67511 | F4: Combustibles | G4: YPF - IMPUESTOS (AB411KE) | H4: $19.898,84
A5: =VLOOKUP(B5,' Empleados c nro legajo'!B:C,2,FALSE) -> 60 | B5: Acuna, Santiago Martin | C5: 46081 | D5: YPF SOCIEDAD ANONIMA | E5: FGAS 1420 67511 | F5: Combustibles | G5: YPF - IMPUESTOS (HQN489) | H5: $10.741,65
A6: =VLOOKUP(B6,' Empleados c nro legajo'!B:C,2,FALSE) -> 39 | B6: Acuña, Mauro Hernan | C6: 46078 | D6: MORTARINI ROMAN ESTEBAN | E6: FGAS 3 1976 | F6: Gastos de comida | G6: SUPERMERCADO QUIROGA 02/2026 | H6: $148.289,26
A7: =VLOOKUP(B7,' Empleados c nro legajo'!B:C,2,FALSE) -> 39 | B7: Acuña, Mauro Hernan | C7: 46081 | D7: YPF SOCIEDAD ANONIMA | E7: FGAS 1420 67511 | F7: Combustibles | G7: YPF - COMBUSTIBLE (OYH556) | H7: $61.239,21
A8: =VLOOKUP(B8,' Empleados c nro legajo'!B:C,2,FALSE) -> 39 | B8: Acuña, Mauro Hernan | C8: 46081 | D8: YPF SOCIEDAD ANONIMA | E8: FGAS 1420 67511 | F8: Combustibles | G8: YPF - IMPUESTOS (OYH556) | H8: $16.193,61
A9: =VLOOKUP(B9,' Empleados c nro legajo'!B:C,2,FALSE) -> 217 | B9: Anca Ezequiel | C9: 46080 | D9: ATRES S.A. | E9: FGAS 12 276 | F9: Gastos de comida | G9: SUPERMERCADO ACTUAL 02/2026 | H9: $258.620,82
A10: =VLOOKUP(B10,' Empleados c nro legajo'!B:C,2,FALSE) -> 217 | B10: Anca Ezequiel | C10: 46081 | D10: YPF SOCIEDAD ANONIMA | E10: FGAS 1420 67511 | F10: Combustibles | G10: YPF - COMBUSTIBLE (FAU092) | H10: $41.599,03
A11: =VLOOKUP(B11,' Empleados c nro legajo'!B:C,2,FALSE) -> 217 | B11: Anca Ezequiel | C11: 46081 | D11: YPF SOCIEDAD ANONIMA | E11: FGAS 1420 67511 | F11: Combustibles | G11: YPF - IMPUESTOS (FAU092) | H11: $11.369,90
A12: =VLOOKUP(B12,' Empleados c nro legajo'!B:C,2,FALSE) -> 301 | B12: Arango Hugo Emmanuel | C12: 46081 | D12: YPF SOCIEDAD ANONIMA | E12: FGAS 1420 67511 | F12: Combustibles | G12: YPF - COMBUSTIBLE (MQK360) | H12: $101.750,72
A13: =VLOOKUP(B13,' Empleados c nro legajo'!B:C,2,FALSE) -> 301 | B13: Arango Hugo Emmanuel | C13: 46081 | D13: YPF SOCIEDAD ANONIMA | E13: FGAS 1420 67511 | F13: Combustibles | G13: YPF - IMPUESTOS (MQK360) | H13: $23.840,02
... A31: =VLOOKUP(B31,' Empleados c nro legajo'!B:C,2,FALSE) -> 12 | B31: Bai, Sebastian | C31: 46087 | D31: POLAND S.A. | E31: FGAS 12 29275 | F31: Gastos de comida | G31: COMPRA LA BLANQUEADA | H31: $26.781,02
A32: =VLOOKUP(B32,' Empleados c nro legajo'!B:C,2,FALSE) -> 12 | B32: Bai, Sebastian | C32: 46100 | D32: ALVAREZ PABLO MARTIN | E32: LG 4 12 | G32: GASTOS BAI -PAGO- | H32: ($186.743,80)
A33: =VLOOKUP(B33,' Empleados c nro legajo'!B:C,2,FALSE) -> 264 | B33: Barrere, Francisco | C33: 46081 | D33: YPF SOCIEDAD ANONIMA | E33: FGAS 1420 67511 | F33: Combustibles | G33: YPF - COMBUSTIBLE (AF643UJ) | H33: $43.503,02
A34: =VLOOKUP(B34,' Empleados c nro legajo'!B:C,2,FALSE) -> 264 | B34: Barrere, Francisco | C34: 46081 | D34: YPF SOCIEDAD ANONIMA | E34: FGAS 1420 67511 | F34: Combustibles | G34: YPF - IMPUESTOS (AF643UJ) | H34: $11.719,27
A35: =VLOOKUP(B35,' Empleados c nro legajo'!B:C,2,FALSE) -> 46 | B35: Beltran, Maximiliano | C35: 46097 | D35: BETANZOS EDUARDO FRANCISCO | E35: FGAS 7 48853 | F35: Gastos varios personal | G35: VALVULA A ESFERA ACC IPS CAÑOS POLIETILENO ERM ACC IPS CAÑO DE POLIETILENO ETT ACC MARRONES ROSCADOS IPS | H35: $54.153,00
A36: =VLOOKUP(B36,' Empleados c nro legajo'!B:C,2,FALSE) -> 46 | B36: Beltran, Maximiliano | C36: 46098 | D36: BETANZOS EDUARDO FRANCISCO | E36: FGAS 7 48889 | F36: FERRETERIA | G36: ACC IPS CAÑO POLIETILENO ERM 3/4 ACC MARRONES ROSCADOS 3/4 VALVULA ESFERA 3/4 ACOPLE 3/4 ACC MARRONES ROSCADOS IPS OSN 3/4 CAÑO POLIETILENO 3/4 | H36: $72.733,88
A37: =VLOOKUP(B37,' Empleados c nro legajo'!B:C,2,FALSE) -> 169 | B37: Buldain Gaston | C37: 46081 | D37: YPF SOCIEDAD ANONIMA | E37: FGAS 1420 67511 | F37: Combustibles | G37: YPF - COMBUSTIBLE (AB559NG) | H37: $69.175,91
A38: =VLOOKUP(B38,' Empleados c nro legajo'!B:C,2,FALSE) -> 169 | B38: Buldain Gaston | C38: 46081 | D38: YPF SOCIEDAD ANONIMA | E38: FGAS 1420 67511 | F38: Combustibles | G38: YPF - IMPUESTOS (AB559NG) | H38: $11.827,44
A39: =VLOOKUP(B39,' Empleados c nro legajo'!B:C,2,FALSE) -> 237 | B39: Burela, Juan Ignacio | C39: 46080 | D39: ATRES S.A. | E39: FGAS 12 276 | F39: Gastos de comida | G39: SUPERMERCADO ACTUAL 02/2026 | H39: $274.234,16
A40: =VLOOKUP(B40,' Empleados c nro legajo'!B:C,2,FALSE) -> 237 | B40: Burela, Juan Ignacio | C40: 46081 | D40: YPF SOCIEDAD ANONIMA | E40: FGAS 1420 67511 | F40: Combustibles | G40: YPF - COMBUSTIBLE (EUE724) | H40: $79.896,72
A41: =VLOOKUP(B41,' Empleados c nro legajo'!B:C,2,FALSE) -> 237 | B41: Burela, Juan Ignacio | C41: 46081 | D41: YPF SOCIEDAD ANONIMA | E41: FGAS 1420 67511 | F41: Combustibles | G41: YPF - IMPUESTOS (EUE724) | H41: $20.208,34
A42: =VLOOKUP(B42,' Empleados c nro legajo'!B:C,2,FALSE) -> 43 | B42: Callegaro, Diego Hernan | C42: 46063 | D42: OCASIONAL | E42: FGAS 2 1842 | F42: Gastos Varios | G42: DISEÑO PURO SA - DIEGO CALLEGARO PAGO | H42: ($13.016,53)
A43: =VLOOKUP(B43,' Empleados c nro legajo'!B:C,2,FALSE) -> 43 | B43: Callegaro, Diego Hernan | C43: 46080 | D43: ATRES S.A. | E43: FGAS 12 276 | F43: Gastos de comida | G43: SUPERMERCADO ACTUAL 02/2026 | H43: $250.860,98
A44: =VLOOKUP(B44,' Empleados c nro legajo'!B:C,2,FALSE) -> 43 | B44: Callegaro, Diego Hernan | C44: 46081 | D44: PETROGUAZZ S.A. | E44: FGAS 48 44525 | F44: Combustibles | G44: PETROGUAZZ - DIEGO CALLEGARO PAGO | H44: ($8.268,09)
... A288: =VLOOKUP(B288,' Empleados c nro legajo'!B:C,2,FALSE) -> 1 | B288: Schmidt, Aldo Walter | C288: 46054 | D288: BONINO NORA BEATRIZ | E288: FGAS 16 26 | F288: Gastos Varios | G288: GASTOS FARMACIA | H288: $29.454,15
A289: =VLOOKUP(B289,' Empleados c nro legajo'!B:C,2,FALSE) -> 1 | B289: Schmidt, Aldo Walter | C289: 46054 | D289: BONINO NORA BEATRIZ | E289: NCR 6 26 | F289: Gastos Varios | G289: WALTER SCHMIDT - PAGO ANULA FACTURA 26
A290: =VLOOKUP(B290,' Empleados c nro legajo'!B:C,2,FALSE) -> 1 | B290: Schmidt, Aldo Walter | C290: 46054 | D290: FERRERE JUAN PATRICIO | E290: FGAS 4 9749 | F290: Mantenimiento | G290: SERRUCHO - REGADERA - AEROSOLES TANZA ROLLO DE CINTA | H290: $20.000,01
A291: =VLOOKUP(B291,' Empleados c nro legajo'!B:C,2,FALSE) -> 1 | B291: Schmidt, Aldo Walter | C291: 46068 | D291: SUPERMERCADO TUTI 2 S.A. | E291: FGAS 47 3590 | F291: Gastos de comida | G291: WALTER SCHMIDT - CTA CTE | H291: $39.581,80
A292: =VLOOKUP(B292,' Empleados c nro legajo'!B:C,2,FALSE) -> 1 | B292: Schmidt, Aldo Walter | C292: 46079 | D292: ALBICI NEUMATICOS SRL | E292: FGAS 6 24671 | F292: Mantenimiento | G292: WALTER SCHMIDT - CTA CTE | H292: $68.595,04
A293: =VLOOKUP(B293,' Empleados c nro legajo'!B:C,2,FALSE) -> 1 | B293: Schmidt, Aldo Walter | C293: 46080 | D293: DJGM COMBUSTIBLES S.A | E293: FGAS 6 27002 | F293: Combustibles | G293: 50% WALTER SCHMIDT CTA CTE - 50% ADMINISTRACION GENERAL | H293: $115.664,08
A294: =VLOOKUP(B294,' Empleados c nro legajo'!B:C,2,FALSE) -> 1 | B294: Schmidt, Aldo Walter | C294: 46080 | D294: ATRES S.A. | E294: FGAS 12 276 | F294: Gastos de comida | G294: SUPERMERCADO ACTUAL 02/2026 | H294: $169.608,68
A295: =VLOOKUP(B295,' Empleados c nro legajo'!B:C,2,FALSE) -> 1 | B295: Schmidt, Aldo Walter | C295: 46083 | D295: MORAS FERNANDO | E295: FGAS 1 276 | F295: Gastos Varios | G295: WALTER SCHMIDT - CTA CTE ARREGLO CRUZE | H295: $158.000,00
A296: =VLOOKUP(B296,' Empleados c nro legajo'!B:C,2,FALSE) -> 1 | B296: Schmidt, Aldo Walter | C296: 46083 | D296: OCASIONAL | E296: FGAS 5 3164 | F296: Gastos Varios | G296: WALTER SCHMITH CTA CTE (HORNO) | H296: $1.750.850,00
A297: =VLOOKUP(B297,' Empleados c nro legajo'!B:C,2,FALSE) -> 1 | B297: Schmidt, Aldo Walter | C297: 46085 | D297: CLERICO VICTOR Y NANNI SILVIA S.H. | E297: FGAS 4 10983 | F297: Mantenimiento | G297: FERRETERIA WALTER PAGO | H297: ($77.695,14)
A298: =VLOOKUP(B298,' Empleados c nro legajo'!B:C,2,FALSE) -> 1 | B298: Schmidt, Aldo Walter | C298: 46086 | D298: POLAND S.A. | E298: FGAS 12 29247 | F298: Gastos de comida | G298: COMPRA LA BLANQUEADA WALTER CTA CTE | H298: $69.606,88
A299: =VLOOKUP(B299,' Empleados c nro legajo'!B:C,2,FALSE) -> 1 | B299: Schmidt, Aldo Walter | C299: 46087 | D299: OLDANI OSVALDO NESTOR | E299: FGAS 3 1819 | F299: Gastos Varios | G299: WALTER SCHMIDT - CTA CTE | H299: $107.024,79
A300: =VLOOKUP(B300,' Empleados c nro legajo'!B:C,2,FALSE) -> 1 | B300: Schmidt, Aldo Walter | C300: 46088 | D300: SUPERMERCADO TUTI 2 S.A. | E300: FGAS 31 4729 | F300: Gastos de comida | G300: SUPERMERCADO WALTER PAGO | H300: ($4.337,98)
...
